<?xml version="1.0"?>
<robot name="robot" xmlns:xacro="http://www.ros.org/wiki/xacro">


  <gazebo>
    <plugin name="gazebo_ros_control" filename="libgazebo_ros_control.so">
    </plugin>
  </gazebo>

<!-- Chassis -->
  <link name="base_link">
      
    <pose>0 0 0.1 0 0 0</pose>
          
    <inertial>      
      <mass value="5"/>      
      <origin rpy="0 0 0" xyz="0 0 0.1"/>      
      <inertia ixx="0.0395416666667" ixy="0" ixz="0"     iyy="0.106208333333" iyz="0" izz="0.106208333333"/>    
    </inertial>
          
    <collision name="collision_chassis">      
      <geometry> 
      <box size = "0.4878 0.8382 0.0381"/>    
      </geometry>    
    </collision>
          
    <visual>      
    <origin rpy="0 0 0" xyz="0 0 0"/>      
    <geometry>        
        <box size = "0.4878 0.8382 0.0381"/>    
    </geometry>
    </visual>  
  </link>
  
  <link name="base_footprint"/>

 <joint name = "base_footprint_joint" type = "fixed">
    <parent link = "base_link"/>
    <child link = "base_footprint"/>
    <origin xyz = "0 0 0"/>
  </joint>


  <link name="link_rotate1">
    <visual>
      <geometry>
        <box size = "0.4878 0.8382 0.0381"/>
      </geometry>
      <origin rpy = "0 0 2.094"/>
    </visual>
    <collision>
        <geometry>
        <box size = "0.4878 0.8382 0.0381"/>    
        </geometry>
    </collision>
  </link>

  <link name="link_rotate2">
    <visual>
      <geometry>
        <box size = "0.4878 0.8382 0.0381"/>
      </geometry>
      <origin rpy = "0 0 -2.094"/>
    </visual>
    <collision>
        <geometry>
        <box size = "0.4878 0.8382 0.0381"/>    
        </geometry>
    </collision>
  </link>

  <joint name = "base_to_rotate_1" type = "fixed">
    <parent link = "base_link"/>
    <child link = "link_rotate1"/>
    <origin xyz = "0 0 0"/>
  </joint>

  <joint name = "base_to_rotate_2" type = "fixed">
    <parent link = "base_link"/>
    <child link = "link_rotate2"/>
    <origin xyz = "0 0 0"/>
  </joint>


<!-- Caster Wheels -->

  <link name ="c_front">
    <visual>
        <geometry>
            <sphere radius = "0.1263" length = "0.0889"/>
        </geometry>
    </visual>
    <collision>
      <geometry>
          <sphere radius = "0.1263" length = "0.0889"/>
      </geometry>
    </collision>
    <inertial>
    <mass value="1" />
      <inertia ixx="1.0" ixy="0.0" ixz="0.0" iyy="1.0" iyz="0.0" izz="1.0" />
    </inertial>
        <gazebo reference="c_front">
      <mu1 value="0.0"/>
      <mu2 value="0.0"/>
      <kp value="10.0" />
      <kd value="1.0" />
      <material>Gazebo/Grey</material>
    </gazebo>  
  </link>

  <link name ="c_back">
    <visual>
        <geometry>
            <sphere radius = "0.1263" length = "0.0889"/>
        </geometry>
    </visual>
    <collision>
        <geometry>
            <sphere radius = "0.1263" length = "0.0889"/>
        </geometry>
    </collision>  
        <inertial>
    <mass value="1" />
      <inertia ixx="1.0" ixy="0.0" ixz="0.0" iyy="1.0" iyz="0.0" izz="1.0" />
    </inertial>
        <gazebo reference="c_back">
      <mu1 value="0.0"/>
      <mu2 value="0.0"/>
      <kp value="10.0" />
      <kd value="1.0" />
      <material>Gazebo/Grey</material>
    </gazebo>  
  </link>


  <joint name = "joint_c_front" type = "fixed">
    <axis xyz = "0 1 0"/>
    <parent link = "base_link"/>
    <child link = "c_front"/>
    <origin xyz = "0.3175 0 0" rpy = "1.5708 0 0"/>
  </joint>

  <joint name = "joint_c_back" type = "fixed">
    <axis xyz = "0 1 0"/>
    <parent link = "base_link"/>
    <child link = "c_back"/>
    <origin xyz = "-0.3175 0 0" rpy = "1.5708 0 0"/>
  </joint>


  <link name="link_right_wheel">        
    <inertial>      
      <mass value="0.2"/>      
      <origin rpy="0 1.5707 1.5707" xyz="0 0 0"/>      
      <inertia ixx="0.00052666666" ixy="0" ixz="0" iyy="0.00052666666" iyz="0" izz="0.001"/>    
    </inertial>
          
    <collision name="link_right_wheel_collision">      
      <origin rpy="0 1.5707 1.5707" xyz="0 0 0" />      
      <geometry>        
        <cylinder length="0.0889" radius="0.127"/>      
      </geometry>    
    </collision> 
        
    <visual name="link_right_wheel_visual">      
      <origin rpy="0 1.5707 1.5707" xyz="0 0.02 0"/>      
      <geometry>        
        <cylinder length="0.0889" radius="0.127"/>      
      </geometry>         
    </visual>   

    <gazebo reference="link_right_wheel">
      <mu1 value="400.0"/>
      <mu2 value="200.0"/>
      <kp value="20" />
      <kd value="1.0" />
      <material>Gazebo/Grey</material>
    </gazebo> 

  </link>

  <link name="link_left_wheel">        
    <inertial>      
      <mass value="0.2"/>      
      <origin rpy="0 1.5707 1.5707" xyz="0 0 0"/>      
      <inertia ixx="0.00052666666" ixy="0" ixz="0" iyy="0.00052666666" iyz="0" izz="0.001"/>    
    </inertial>
          
    <collision name="link_left_wheel_collision">      
      <origin rpy="0 1.5707 1.5707" xyz="0 0 0" />      
      <geometry>        
        <cylinder length="0.0889" radius="0.127"/>      
      </geometry>    
    </collision> 
        
    <visual name="link_left_wheel_visual">      
      <origin rpy="0 1.5707 1.5707" xyz="0 0.02 0"/>      
      <geometry>        
        <cylinder length="0.0889" radius="0.127"/>      
      </geometry>         
    </visual>   

    <gazebo reference="link_left_wheel">
      <mu1 value="400.0"/>
      <mu2 value="200.0"/>
      <kp value="20" />
      <kd value="1.0" />
      <material>Gazebo/Grey</material>
    </gazebo> 

  </link>

  <joint name="joint_right_wheel" type="continuous">    
    <origin rpy="0 0 0" xyz="0 0.3175 0"/>    <!-- 0 0 0 -->
    <child link="link_right_wheel" />    
    <parent link="base_link"/>    
    <axis rpy="0 0 0" xyz="0 1 0"/>    
    <limit effort="10000" velocity="1000"/>    
    <joint_properties damping="1.0" friction="1.0" />  
  </joint>

  <joint name="joint_left_wheel" type="continuous">    
    <origin rpy = "0 0 0" xyz = "0 -0.3175 0"/>    <!-- 0 0 0 -->
    <child link="link_left_wheel" />    
    <parent link="base_link"/>    
    <axis rpy="0 0 0" xyz="0 1 0"/>    
    <limit effort="10000" velocity="1000"/>    
    <joint_properties damping="1.0" friction="1.0" />  
  </joint>


  <transmission name="right_wheel_transmission">
    <type>transmission_interface/SimpleTransmission</type>
    <joint name="joint_right_wheel">
      <hardwareInterface>hardware_interface/VelocityJointInterface</hardwareInterface>
    </joint> 
    <actuator name="right_wheel_actuator">        
      <mechanicalReduction>1</mechanicalReduction>    
       <hardwareInterface>hardware_interface/VelocityJointInterface</hardwareInterface>
    </actuator> 
  </transmission>


  <transmission name="left_wheel_transmission">
    <type>transmission_interface/SimpleTransmission</type>
    <joint name="joint_left_wheel">
      <hardwareInterface>hardware_interface/VelocityJointInterface</hardwareInterface>
    </joint> 
    <actuator name="left_wheel_actuator">        
      <mechanicalReduction>1</mechanicalReduction>    
        <hardwareInterface>hardware_interface/VelocityJointInterface</hardwareInterface>

    </actuator> 
  </transmission>


  <!-- camera link -->
  <gazebo reference="camera_link">
      <material>Gazebo/Red</material>

      <sensor name="camera" type="depth">
          <pose> 0 0 0 0 0 0 </pose>
          <visualize>true</visualize>
          <update_rate>10</update_rate>
          <camera>
            <horizontal_fov>2</horizontal_fov>
            <image>
              <format>A8R8G8B8</format>
              <width>1920</width>
              <height>1080</height>
            </image>
            <clip>
              <near>0.05</near>
              <far>8</far>
            </clip>
          </camera>
          <plugin name="camera_controller" filename="libgazebo_ros_camera.so">
              <frame_name>camera_link_optical</frame_name>
          </plugin>
      </sensor>
  </gazebo>

  <joint name="camera_joint" type="fixed">
      <parent link="base_link"/>
      <child link="camera_link"/>
      <origin xyz="0 0 1.5" rpy="0 0.55 0"/>
  </joint>

  <link name="camera_link">
      <visual>
          <geometry>
              <box size="0.01 0.1 0.035"/>
          </geometry>
          <material name="red"/>
      </visual>
  </link>


  <joint name="camera_optical_joint" type="fixed">
      <parent link="camera_link"/>
      <child link="camera_link_optical"/>
      <origin xyz="0 0 0" rpy="-1.55 0 -1.55"/>
  </joint>

  <link name="camera_link_optical"></link>
</robot>



