<?xml version="1.0"?>
<sdf version='1.7'>
  <world name='default'>
    <light name='sun' type='directional'>
      <cast_shadows>1</cast_shadows>
      <pose>0 0 10 0 -0 0</pose>
      <diffuse>0.8 0.8 0.8 1</diffuse>
      <specular>0.2 0.2 0.2 1</specular>
      <attenuation>
        <range>1000</range>
        <constant>0.9</constant>
        <linear>0.01</linear>
        <quadratic>0.001</quadratic>
      </attenuation>
      <direction>-0.5 0.1 -0.9</direction>
      <spot>
        <inner_angle>0</inner_angle>
        <outer_angle>0</outer_angle>
        <falloff>0</falloff>
      </spot>
    </light>
    <gravity>0 0 -9.8</gravity>
    <magnetic_field>6e-06 2.3e-05 -4.2e-05</magnetic_field>
    <atmosphere type='adiabatic'/>
    <physics type='ode'>
      <max_step_size>0.001</max_step_size>
      <real_time_factor>1</real_time_factor>
      <real_time_update_rate>1000</real_time_update_rate>
    </physics>
    <scene>
      <ambient>0.4 0.4 0.4 1</ambient>
      <background>0.7 0.7 0.7 1</background>
      <shadows>1</shadows>
    </scene>
    <wind/>
    <spherical_coordinates>
      <surface_model>EARTH_WGS84</surface_model>
      <latitude_deg>0</latitude_deg>
      <longitude_deg>0</longitude_deg>
      <elevation>0</elevation>
      <heading_deg>0</heading_deg>
    </spherical_coordinates>
    <model name='robot'>
      <link name='base_link'>
        <inertial>
          <pose>0 0 0.071429 0 -0 0</pose>
          <mass>7</mass>
          <inertia>
            <ixx>2.05383</ixx>
            <ixy>0</ixy>
            <ixz>0</ixz>
            <iyy>2.32211</iyy>
            <iyz>0</iyz>
            <izz>2.30782</izz>
          </inertia>
        </inertial>
        <collision name='base_link_fixed_joint_lump__collision_chassis_collision'>
          <pose>0 0 0 0 -0 0</pose>
          <geometry>
            <box>
              <size>0.4878 0.8382 0.0381</size>
            </box>
          </geometry>
          <max_contacts>10</max_contacts>
          <surface>
            <contact>
              <ode/>
            </contact>
            <bounce/>
            <friction>
              <torsional>
                <ode/>
              </torsional>
              <ode/>
            </friction>
          </surface>
        </collision>
        <collision name='base_link_fixed_joint_lump__link_rotate1_collision_1'>
          <pose>0 0 0 0 -0 0</pose>
          <geometry>
            <box>
              <size>0.4878 0.8382 0.0381</size>
            </box>
          </geometry>
          <max_contacts>10</max_contacts>
          <surface>
            <contact>
              <ode/>
            </contact>
            <bounce/>
            <friction>
              <torsional>
                <ode/>
              </torsional>
              <ode/>
            </friction>
          </surface>
        </collision>
        <collision name='base_link_fixed_joint_lump__link_rotate2_collision_2'>
          <pose>0 0 0 0 -0 0</pose>
          <geometry>
            <box>
              <size>0.4878 0.8382 0.0381</size>
            </box>
          </geometry>
          <max_contacts>10</max_contacts>
          <surface>
            <contact>
              <ode/>
            </contact>
            <bounce/>
            <friction>
              <torsional>
                <ode/>
              </torsional>
              <ode/>
            </friction>
          </surface>
        </collision>
        <collision name='base_link_fixed_joint_lump__c_back_collision_3'>
          <pose>-0.3175 0 0 1.5708 -0 0</pose>
          <geometry>
            <sphere>
              <radius>0.1263</radius>
            </sphere>
          </geometry>
          <max_contacts>10</max_contacts>
          <surface>
            <contact>
              <ode/>
            </contact>
            <bounce/>
            <friction>
              <torsional>
                <ode/>
              </torsional>
              <ode/>
            </friction>
          </surface>
        </collision>
        <collision name='base_link_fixed_joint_lump__c_front_collision_4'>
          <pose>0.3175 0 0 1.5708 -0 0</pose>
          <geometry>
            <sphere>
              <radius>0.1263</radius>
            </sphere>
          </geometry>
          <max_contacts>10</max_contacts>
          <surface>
            <contact>
              <ode/>
            </contact>
            <bounce/>
            <friction>
              <torsional>
                <ode/>
              </torsional>
              <ode/>
            </friction>
          </surface>
        </collision>
        <visual name='base_link_visual'>
          <pose>0 0 0 0 -0 0</pose>
          <geometry>
            <box>
              <size>0.4878 0.8382 0.0381</size>
            </box>
          </geometry>
        </visual>
        <visual name='base_link_fixed_joint_lump__link_rotate1_visual_1'>
          <pose>0 0 0 0 -0 2.094</pose>
          <geometry>
            <box>
              <size>0.4878 0.8382 0.0381</size>
            </box>
          </geometry>
        </visual>
        <visual name='base_link_fixed_joint_lump__link_rotate2_visual_2'>
          <pose>0 0 0 0 0 -2.094</pose>
          <geometry>
            <box>
              <size>0.4878 0.8382 0.0381</size>
            </box>
          </geometry>
        </visual>
        <visual name='base_link_fixed_joint_lump__camera_link_visual_3'>
          <pose>0 0 1.5 0 0.55 0</pose>
          <geometry>
            <box>
              <size>0.01 0.1 0.035</size>
            </box>
          </geometry>
          <material>
            <script>
              <name>Gazebo/Red</name>
              <uri>file://media/materials/scripts/gazebo.material</uri>
            </script>
          </material>
        </visual>
        <visual name='base_link_fixed_joint_lump__c_back_visual_4'>
          <pose>-0.3175 0 0 1.5708 -0 0</pose>
          <geometry>
            <sphere>
              <radius>0.1263</radius>
            </sphere>
          </geometry>
        </visual>
        <visual name='base_link_fixed_joint_lump__c_front_visual_5'>
          <pose>0.3175 0 0 1.5708 -0 0</pose>
          <geometry>
            <sphere>
              <radius>0.1263</radius>
            </sphere>
          </geometry>
        </visual>
        <sensor name='camera' type='depth'>
          <visualize>1</visualize>
          <update_rate>10</update_rate>
          <camera>
            <horizontal_fov>2</horizontal_fov>
            <image>
              <format>A8R8G8B8</format>
              <width>1920</width>
              <height>1080</height>
            </image>
            <clip>
              <near>0.05</near>
              <far>8</far>
            </clip>
          </camera>
          <plugin name='camera_controller' filename='libgazebo_ros_camera.so'>
            <frame_name>camera_link_optical</frame_name>
            <robotNamespace>/</robotNamespace>
          </plugin>
          <pose>0 0 1.5 0 0.55 0</pose>
        </sensor>
        <self_collide>0</self_collide>
        <enable_wind>0</enable_wind>
        <kinematic>0</kinematic>
      </link>
      <joint name='joint_left_wheel' type='revolute'>
        <pose relative_to='base_link'>0 -0.3175 0 0 -0 0</pose>
        <parent>base_link</parent>
        <child>link_left_wheel</child>
        <axis>
          <xyz>0 1 0</xyz>
          <limit>
            <effort>10000</effort>
            <velocity>1000</velocity>
            <lower>-1e+16</lower>
            <upper>1e+16</upper>
          </limit>
          <dynamics>
            <spring_reference>0</spring_reference>
            <spring_stiffness>0</spring_stiffness>
          </dynamics>
        </axis>
      </joint>
      <link name='link_left_wheel'>
        <pose relative_to='joint_left_wheel'>0 0 0 0 -0 0</pose>
        <inertial>
          <pose>0 0 0 -0 1.5707 1.5707</pose>
          <mass>0.2</mass>
          <inertia>
            <ixx>0.000526667</ixx>
            <ixy>0</ixy>
            <ixz>0</ixz>
            <iyy>0.000526667</iyy>
            <iyz>0</iyz>
            <izz>0.001</izz>
          </inertia>
        </inertial>
        <collision name='link_left_wheel_collision_collision'>
          <pose>0 0 0 1.57089 1.57079 -3.14159</pose>
          <geometry>
            <cylinder>
              <length>0.0889</length>
              <radius>0.127</radius>
            </cylinder>
          </geometry>
          <max_contacts>10</max_contacts>
          <surface>
            <contact>
              <ode/>
            </contact>
            <bounce/>
            <friction>
              <torsional>
                <ode/>
              </torsional>
              <ode/>
            </friction>
          </surface>
        </collision>
        <visual name='link_left_wheel_visual_visual'>
          <pose>0 0.02 0 1.57089 1.57079 -3.14159</pose>
          <geometry>
            <cylinder>
              <length>0.0889</length>
              <radius>0.127</radius>
            </cylinder>
          </geometry>
        </visual>
        <self_collide>0</self_collide>
        <enable_wind>0</enable_wind>
        <kinematic>0</kinematic>
      </link>
      <joint name='joint_right_wheel' type='revolute'>
        <pose relative_to='base_link'>0 0.3175 0 0 -0 0</pose>
        <parent>base_link</parent>
        <child>link_right_wheel</child>
        <axis>
          <xyz>0 1 0</xyz>
          <limit>
            <effort>10000</effort>
            <velocity>1000</velocity>
            <lower>-1e+16</lower>
            <upper>1e+16</upper>
          </limit>
          <dynamics>
            <spring_reference>0</spring_reference>
            <spring_stiffness>0</spring_stiffness>
          </dynamics>
        </axis>
      </joint>
      <link name='link_right_wheel'>
        <pose relative_to='joint_right_wheel'>0 0 0 0 -0 0</pose>
        <inertial>
          <pose>0 0 0 -0 1.5707 1.5707</pose>
          <mass>0.2</mass>
          <inertia>
            <ixx>0.000526667</ixx>
            <ixy>0</ixy>
            <ixz>0</ixz>
            <iyy>0.000526667</iyy>
            <iyz>0</iyz>
            <izz>0.001</izz>
          </inertia>
        </inertial>
        <collision name='link_right_wheel_collision_collision'>
          <pose>0 0 0 1.57089 1.57079 -3.14159</pose>
          <geometry>
            <cylinder>
              <length>0.0889</length>
              <radius>0.127</radius>
            </cylinder>
          </geometry>
          <max_contacts>10</max_contacts>
          <surface>
            <contact>
              <ode/>
            </contact>
            <bounce/>
            <friction>
              <torsional>
                <ode/>
              </torsional>
              <ode/>
            </friction>
          </surface>
        </collision>
        <visual name='link_right_wheel_visual_visual'>
          <pose>0 0.02 0 1.57089 1.57079 -3.14159</pose>
          <geometry>
            <cylinder>
              <length>0.0889</length>
              <radius>0.127</radius>
            </cylinder>
          </geometry>
        </visual>
        <self_collide>0</self_collide>
        <enable_wind>0</enable_wind>
        <kinematic>0</kinematic>
      </link>
      <static>0</static>
      <plugin name='gazebo_ros_control' filename='libgazebo_ros_control.so'>
        <robotNamespace>/</robotNamespace>
      </plugin>
      <pose>0 0 1 0 -0 0</pose>
    </model>
    <model name='my_ground_plane'>
      <static>1</static>
      <link name='link'>
        <collision name='collision'>
          <geometry>
            <plane>
              <normal>0 0 1</normal>
              <size>79 57</size>
            </plane>
          </geometry>
          <surface>
            <friction>
              <ode>
                <mu>100</mu>
                <mu2>50</mu2>
              </ode>
              <torsional>
                <ode/>
              </torsional>
            </friction>
            <contact>
              <ode/>
            </contact>
            <bounce/>
          </surface>
          <max_contacts>10</max_contacts>
        </collision>
        <visual name='visual'>
          <cast_shadows>0</cast_shadows>
          <geometry>
            <plane>
              <normal>0 0 1</normal>
              <size>79 57</size>
            </plane>
          </geometry>
          <material>
            <script>
              <uri>model://my_ground_plane/materials/scripts</uri>
              <uri>model://my_ground_plane/materials/textures/</uri>
              <name>MyGroundPlane/Image</name>
            </script>
          </material>
        </visual>
        <self_collide>0</self_collide>
        <enable_wind>0</enable_wind>
        <kinematic>0</kinematic>
      </link>
      <pose>-0.166074 0.494407 0 0 -0 0</pose>
    </model>
    <state world_name='default'>
      <sim_time>66 587000000</sim_time>
      <real_time>67 534893039</real_time>
      <wall_time>1731592928 537817953</wall_time>
      <iterations>66587</iterations>
      <model name='my_ground_plane'>
        <pose>-0.166074 0.494407 0 0 -0 0</pose>
        <scale>1 1 1</scale>
        <link name='link'>
          <pose>-0.166074 0.494407 0 0 -0 0</pose>
          <velocity>0 0 0 0 -0 0</velocity>
          <acceleration>0 0 0 0 -0 0</acceleration>
          <wrench>0 0 0 0 -0 0</wrench>
        </link>
      </model>
      <model name='robot'>
        <pose>25.5758 -2.54361 0.126998 1e-06 0.001595 1.56211</pose>
        <scale>1 1 1</scale>
        <link name='base_link'>
          <pose>25.5758 -2.54361 0.126998 1e-06 0.001595 1.56211</pose>
          <velocity>0.000138 -0.000384 -4.1e-05 0.003 -7.5e-05 3.1e-05</velocity>
          <acceleration>-0.005469 0.00075 0.009031 -0.00273 -0.01631 0.000494</acceleration>
          <wrench>-0.038283 0.005252 0.063219 0 -0 0</wrench>
        </link>
        <link name='link_left_wheel'>
          <pose>25.8933 -2.54637 0.127 1.5e-05 0.004075 1.56211</pose>
          <velocity>0.000103 -0.000374 2.1e-05 0.002942 0.000604 2.4e-05</velocity>
          <acceleration>0.000647 0.000642 0.001637 -0.002693 0.005 0.000453</acceleration>
          <wrench>0.000129 0.000128 0.000327 0 -0 0</wrench>
        </link>
        <link name='link_right_wheel'>
          <pose>25.2583 -2.54085 0.127001 -1.9e-05 -0.000832 1.56211</pose>
          <velocity>0.000122 -0.000394 -4.2e-05 0.003106 0.001147 2.6e-05</velocity>
          <acceleration>-0.005915 0.000353 0.00069 -0.001673 -0.095363 0.001041</acceleration>
          <wrench>-0.001183 7.1e-05 0.000138 0 -0 0</wrench>
        </link>
      </model>
      <light name='sun'>
        <pose>0 0 10 0 -0 0</pose>
      </light>
    </state>
    <gui fullscreen='0'>
      <camera name='user_camera'>
        <pose>26.0201 -22.8158 11.5565 -0 0.535643 1.9082</pose>
        <view_controller>orbit</view_controller>
        <projection_type>perspective</projection_type>
      </camera>
    </gui>
  </world>
</sdf>
